2024-03-13 15:40:42,376 - pyswarms.backend.generators - ERROR - Bounds and/or init_pos should be of size (1,)
Traceback (most recent call last):
  File "C:\Users\82516\.conda\envs\tf1\lib\site-packages\pyswarms\backend\generators.py", line 74, in generate_swarm
    lb, ub = bounds
ValueError: not enough values to unpack (expected 2, got 1)
2024-03-13 15:48:06,247 - pyswarms.backend.generators - ERROR - Bounds and/or init_pos should be of size (1,)
Traceback (most recent call last):
  File "C:\Users\82516\.conda\envs\tf1\lib\site-packages\pyswarms\backend\generators.py", line 74, in generate_swarm
    lb, ub = bounds
ValueError: not enough values to unpack (expected 2, got 1)
2024-03-13 16:03:34,415 - pyswarms.backend.generators - ERROR - Bounds and/or init_pos should be of size (1,)
Traceback (most recent call last):
  File "C:\Users\82516\.conda\envs\tf1\lib\site-packages\pyswarms\backend\generators.py", line 74, in generate_swarm
    lb, ub = bounds
ValueError: not enough values to unpack (expected 2, got 1)
2024-03-20 09:29:54,009 - pyswarms.backend.generators - ERROR - Bounds and/or init_pos should be of size (1,)
Traceback (most recent call last):
  File "C:\Users\82516\.conda\envs\tf1\lib\site-packages\pyswarms\backend\generators.py", line 74, in generate_swarm
    lb, ub = bounds
ValueError: not enough values to unpack (expected 2, got 1)
2024-03-20 10:04:58,403 - pyswarms.single.global_best - INFO - Optimize for 1000 iters with {'c1': 1.5, 'c2': 1.5, 'w': 0.5}
2024-03-20 10:05:02,455 - pyswarms.single.global_best - INFO - Optimization finished | best cost: 0.026026323091444644, best pos: [-2.05303089  1.03706884  1.93804127 -1.23078472 -0.43631707 -1.40235015]
2024-03-20 10:08:02,197 - pyswarms.backend.generators - ERROR - Bounds and/or init_pos should be of size (1,)
Traceback (most recent call last):
  File "C:\Users\82516\.conda\envs\tf1\lib\site-packages\pyswarms\backend\generators.py", line 82, in generate_swarm
    low=min_bounds, high=max_bounds, size=(n_particles, dimensions)
  File "mtrand.pyx", line 1131, in numpy.random.mtrand.RandomState.uniform
  File "_common.pyx", line 562, in numpy.random._common.cont
  File "_common.pyx", line 480, in numpy.random._common.cont_broadcast_2
  File "_common.pyx", line 229, in numpy.random._common.validate_output_shape
ValueError: Output size (20, 1) is not compatible with broadcast dimensions of inputs (20, 6).
2024-03-20 10:08:12,410 - pyswarms.backend.generators - ERROR - Bounds and/or init_pos should be of size (1,)
Traceback (most recent call last):
  File "C:\Users\82516\.conda\envs\tf1\lib\site-packages\pyswarms\backend\generators.py", line 82, in generate_swarm
    low=min_bounds, high=max_bounds, size=(n_particles, dimensions)
  File "mtrand.pyx", line 1131, in numpy.random.mtrand.RandomState.uniform
  File "_common.pyx", line 562, in numpy.random._common.cont
  File "_common.pyx", line 480, in numpy.random._common.cont_broadcast_2
  File "_common.pyx", line 229, in numpy.random._common.validate_output_shape
ValueError: Output size (20, 1) is not compatible with broadcast dimensions of inputs (20, 6).
